ERROR:root:Testing
INFO:werkzeug: * Running on http://127.0.0.1:5000/ (Press CTRL+C to quit)
ERROR:root:Testing
INFO:werkzeug: * Running on http://127.0.0.1:5000/ (Press CTRL+C to quit)
root - ERROR - Testing
werkzeug - INFO -  * Running on http://127.0.0.1:5000/ (Press CTRL+C to quit)
2021-03-30 12:45:48,833- ERROR - Testing
2021-03-30 12:45:48,863- INFO -  * Running on http://127.0.0.1:5000/ (Press CTRL+C to quit)
2021-03-30 12:47:07,020- ERROR - Testing
2021-03-30 12:47:07,047- INFO -  * Running on http://127.0.0.1:5000/ (Press CTRL+C to quit)
2021-03-30 12:48:05,759- ERROR - Testing
2021-03-30 12:48:05,785- INFO -  * Running on http://127.0.0.1:5000/ (Press CTRL+C to quit)
2021-03-30 12:56:59,441- INFO -  * Running on http://127.0.0.1:5000/ (Press CTRL+C to quit)
2021-03-30 12:57:12,792- ERROR - {'Status': 'User already registered Please provide different values '}
2021-03-30 12:57:12,793- INFO - 127.0.0.1 - - [30/Mar/2021 12:57:12] "[37mPOST /cogbank/1.0/register/ HTTP/1.1[0m" 202 -
2021-03-30 12:58:31,576- ERROR - {'Status': 'User already registered Please provide different values '}
2021-03-30 12:58:31,577- INFO - 127.0.0.1 - - [30/Mar/2021 12:58:31] "[37mPOST /cogbank/1.0/register/ HTTP/1.1[0m" 202 -
2021-03-30 12:58:37,755- INFO -  * Running on http://127.0.0.1:5000/ (Press CTRL+C to quit) - 113
2021-03-30 12:58:55,719- ERROR - {'Status': 'User already registered Please provide different values '} - 155
2021-03-30 12:58:55,720- INFO - 127.0.0.1 - - [30/Mar/2021 12:58:55] "[37mPOST /cogbank/1.0/register/ HTTP/1.1[0m" 202 - - 113
2021-03-30 12:59:59,707- INFO -  * Running on http://127.0.0.1:5000/ (Press CTRL+C to quit) - _internal - 113
2021-03-30 13:00:02,056- ERROR - {'Status': 'User already registered Please provide different values '} - app - 155
2021-03-30 13:00:02,057- INFO - 127.0.0.1 - - [30/Mar/2021 13:00:02] "[37mPOST /cogbank/1.0/register/ HTTP/1.1[0m" 202 - - _internal - 113
2021-03-30 13:01:03,072- INFO -  * Running on http://127.0.0.1:5000/ (Press CTRL+C to quit) - _internal - 113 - 16368 - MainProcess
2021-03-30 13:01:06,043- ERROR - {'Status': 'User already registered Please provide different values '} - app - 155 - 16368 - MainProcess
2021-03-30 13:01:06,044- INFO - 127.0.0.1 - - [30/Mar/2021 13:01:06] "[37mPOST /cogbank/1.0/register/ HTTP/1.1[0m" 202 - - _internal - 113 - 16368 - MainProcess
2021-03-30 13:03:27,114- INFO -  _internal -  113 -  * Running on http://127.0.0.1:5000/ (Press CTRL+C to quit)
2021-03-30 13:03:30,059- ERROR -  app -  155 - {'Status': 'User already registered Please provide different values '}
2021-03-30 13:03:30,060- INFO -  _internal -  113 - 127.0.0.1 - - [30/Mar/2021 13:03:30] "[37mPOST /cogbank/1.0/register/ HTTP/1.1[0m" 202 -
2021-03-30 13:05:37,019- INFO -  _internal -  113 -  * Running on http://127.0.0.1:5000/ (Press CTRL+C to quit)
2021-03-30 13:05:38,953- ERROR -  app -  157 - {'Status': 'User already registered Please provide different values '}
2021-03-30 13:05:38,954- INFO -  _internal -  113 - 127.0.0.1 - - [30/Mar/2021 13:05:38] "[37mPOST /cogbank/1.0/register/ HTTP/1.1[0m" 202 -
2021-03-30 13:06:25,390- INFO -  _internal -  113 -  * Running on http://127.0.0.1:5000/ (Press CTRL+C to quit)
2021-03-30 13:06:26,828- ERROR -  app -  157 - {'Status': 'User already registered Please provide different values '}
2021-03-30 13:06:26,829- INFO -  _internal -  113 - 127.0.0.1 - - [30/Mar/2021 13:06:26] "[37mPOST /cogbank/1.0/register/ HTTP/1.1[0m" 202 -
2021-03-30 13:14:36,662- ERROR -  app -  339 - {'Status': 'User has already applied loan. Only one loan can be applied'}
2021-03-30 13:14:36,663- INFO -  _internal -  113 - 127.0.0.1 - - [30/Mar/2021 13:14:36] "[37mPOST /cogbank/1.0/applyLoan/ HTTP/1.1[0m" 202 -
2021-03-30 13:15:23,452- INFO -  _internal -  113 -  * Running on http://127.0.0.1:5000/ (Press CTRL+C to quit)
2021-03-30 13:15:47,513- INFO -  _internal -  113 - 127.0.0.1 - - [30/Mar/2021 13:15:47] "[37mPOST /cogbank/1.0/register/ HTTP/1.1[0m" 200 -
2021-03-30 13:17:47,032- INFO -  _internal -  113 -  * Running on http://127.0.0.1:5000/ (Press CTRL+C to quit)
2021-03-30 13:17:50,035- ERROR -  app -  153 - {'Status': 'User already registered Please provide different values '}
2021-03-30 13:17:50,036- INFO -  _internal -  113 - 127.0.0.1 - - [30/Mar/2021 13:17:50] "[37mPOST /cogbank/1.0/register/ HTTP/1.1[0m" 202 -
2021-03-30 13:18:11,180- ERROR -  app -  183 - (builtins.ValueError) could not convert string to float: 'dem2'
[SQL: INSERT INTO user (name, username, email, password, address, state, country, pan, "contactNumber", dob) VALUES (?, ?, ?, ?, ?, ?, ?, ?, ?, ?)]
[parameters: [{'name': 'dem3', 'email': 'dem3@1google.com', 'username': 'dem3', 'pan': '69623267dema3', 'dob': '30-Mar-2021', 'address': 'dem2', 'contactNumber': '0897645390', 'password': 'sha256$HWwhK9fk$c7afc858c22069a63a9fce11dd758b46d5e9ff22ccadc621908bafc6ea18af13', 'state': 'dem2', 'country': 'dem2'}]]
Traceback (most recent call last):
  File "c:\users\javacloudmc597\.virtualenvs\day12-bmnoo7rb\lib\site-packages\sqlalchemy\engine\base.py", line 1608, in _execute_context
    context = constructor(
  File "c:\users\javacloudmc597\.virtualenvs\day12-bmnoo7rb\lib\site-packages\sqlalchemy\engine\default.py", line 1011, in _init_compiled
    param = [
  File "c:\users\javacloudmc597\.virtualenvs\day12-bmnoo7rb\lib\site-packages\sqlalchemy\engine\default.py", line 1012, in <listcomp>
    processors[key](compiled_params[key])
ValueError: could not convert string to float: 'dem2'

The above exception was the direct cause of the following exception:

Traceback (most recent call last):
  File "C:\Users\javacloudmc597\Documents\PythonLearning\Day12\app.py", line 169, in register
    db.session.commit()
  File "<string>", line 2, in commit
  File "c:\users\javacloudmc597\.virtualenvs\day12-bmnoo7rb\lib\site-packages\sqlalchemy\orm\session.py", line 1415, in commit
    self._transaction.commit(_to_root=self.future)
  File "c:\users\javacloudmc597\.virtualenvs\day12-bmnoo7rb\lib\site-packages\sqlalchemy\orm\session.py", line 829, in commit
    self._prepare_impl()
  File "c:\users\javacloudmc597\.virtualenvs\day12-bmnoo7rb\lib\site-packages\sqlalchemy\orm\session.py", line 808, in _prepare_impl
    self.session.flush()
  File "c:\users\javacloudmc597\.virtualenvs\day12-bmnoo7rb\lib\site-packages\sqlalchemy\orm\session.py", line 3233, in flush
    self._flush(objects)
  File "c:\users\javacloudmc597\.virtualenvs\day12-bmnoo7rb\lib\site-packages\sqlalchemy\orm\session.py", line 3373, in _flush
    transaction.rollback(_capture_exception=True)
  File "c:\users\javacloudmc597\.virtualenvs\day12-bmnoo7rb\lib\site-packages\sqlalchemy\util\langhelpers.py", line 70, in __exit__
    compat.raise_(
  File "c:\users\javacloudmc597\.virtualenvs\day12-bmnoo7rb\lib\site-packages\sqlalchemy\util\compat.py", line 198, in raise_
    raise exception
  File "c:\users\javacloudmc597\.virtualenvs\day12-bmnoo7rb\lib\site-packages\sqlalchemy\orm\session.py", line 3333, in _flush
    flush_context.execute()
  File "c:\users\javacloudmc597\.virtualenvs\day12-bmnoo7rb\lib\site-packages\sqlalchemy\orm\unitofwork.py", line 453, in execute
    rec.execute(self)
  File "c:\users\javacloudmc597\.virtualenvs\day12-bmnoo7rb\lib\site-packages\sqlalchemy\orm\unitofwork.py", line 627, in execute
    util.preloaded.orm_persistence.save_obj(
  File "c:\users\javacloudmc597\.virtualenvs\day12-bmnoo7rb\lib\site-packages\sqlalchemy\orm\persistence.py", line 242, in save_obj
    _emit_insert_statements(
  File "c:\users\javacloudmc597\.virtualenvs\day12-bmnoo7rb\lib\site-packages\sqlalchemy\orm\persistence.py", line 1219, in _emit_insert_statements
    result = connection._execute_20(
  File "c:\users\javacloudmc597\.virtualenvs\day12-bmnoo7rb\lib\site-packages\sqlalchemy\engine\base.py", line 1520, in _execute_20
    return meth(self, args_10style, kwargs_10style, execution_options)
  File "c:\users\javacloudmc597\.virtualenvs\day12-bmnoo7rb\lib\site-packages\sqlalchemy\sql\elements.py", line 313, in _execute_on_connection
    return connection._execute_clauseelement(
  File "c:\users\javacloudmc597\.virtualenvs\day12-bmnoo7rb\lib\site-packages\sqlalchemy\engine\base.py", line 1389, in _execute_clauseelement
    ret = self._execute_context(
  File "c:\users\javacloudmc597\.virtualenvs\day12-bmnoo7rb\lib\site-packages\sqlalchemy\engine\base.py", line 1614, in _execute_context
    self._handle_dbapi_exception(
  File "c:\users\javacloudmc597\.virtualenvs\day12-bmnoo7rb\lib\site-packages\sqlalchemy\engine\base.py", line 1929, in _handle_dbapi_exception
    util.raise_(
  File "c:\users\javacloudmc597\.virtualenvs\day12-bmnoo7rb\lib\site-packages\sqlalchemy\util\compat.py", line 198, in raise_
    raise exception
  File "c:\users\javacloudmc597\.virtualenvs\day12-bmnoo7rb\lib\site-packages\sqlalchemy\engine\base.py", line 1608, in _execute_context
    context = constructor(
  File "c:\users\javacloudmc597\.virtualenvs\day12-bmnoo7rb\lib\site-packages\sqlalchemy\engine\default.py", line 1011, in _init_compiled
    param = [
  File "c:\users\javacloudmc597\.virtualenvs\day12-bmnoo7rb\lib\site-packages\sqlalchemy\engine\default.py", line 1012, in <listcomp>
    processors[key](compiled_params[key])
sqlalchemy.exc.StatementError: (builtins.ValueError) could not convert string to float: 'dem2'
[SQL: INSERT INTO user (name, username, email, password, address, state, country, pan, "contactNumber", dob) VALUES (?, ?, ?, ?, ?, ?, ?, ?, ?, ?)]
[parameters: [{'name': 'dem3', 'email': 'dem3@1google.com', 'username': 'dem3', 'pan': '69623267dema3', 'dob': '30-Mar-2021', 'address': 'dem2', 'contactNumber': '0897645390', 'password': 'sha256$HWwhK9fk$c7afc858c22069a63a9fce11dd758b46d5e9ff22ccadc621908bafc6ea18af13', 'state': 'dem2', 'country': 'dem2'}]]
2021-03-30 13:18:11,289- INFO -  _internal -  113 - 127.0.0.1 - - [30/Mar/2021 13:18:11] "[31m[1mPOST /cogbank/1.0/register/ HTTP/1.1[0m" 400 -
2021-03-30 13:19:38,606- INFO -  _internal -  113 -  * Running on http://127.0.0.1:5000/ (Press CTRL+C to quit)
2021-03-30 13:19:40,736- ERROR -  app -  183 - (builtins.ValueError) could not convert string to float: 'dem2'
[SQL: INSERT INTO user (name, username, email, password, address, state, country, pan, "contactNumber", dob) VALUES (?, ?, ?, ?, ?, ?, ?, ?, ?, ?)]
[parameters: [{'username': 'dem3', 'address': 'dem2', 'state': 'dem2', 'country': 'dem2', 'pan': '69623267dema3', 'email': 'dem3@1google.com', 'contactNumber': '0897645390', 'name': 'dem3', 'dob': '30-Mar-2021', 'password': 'sha256$TTx0fj8r$cd23ed8ce4d5365a78386a8a8c485d37f7edad95ebba594eacc5c060bc52ac7e'}]]
Traceback (most recent call last):
  File "c:\users\javacloudmc597\.virtualenvs\day12-bmnoo7rb\lib\site-packages\sqlalchemy\engine\base.py", line 1608, in _execute_context
    context = constructor(
  File "c:\users\javacloudmc597\.virtualenvs\day12-bmnoo7rb\lib\site-packages\sqlalchemy\engine\default.py", line 1011, in _init_compiled
    param = [
  File "c:\users\javacloudmc597\.virtualenvs\day12-bmnoo7rb\lib\site-packages\sqlalchemy\engine\default.py", line 1012, in <listcomp>
    processors[key](compiled_params[key])
ValueError: could not convert string to float: 'dem2'

The above exception was the direct cause of the following exception:

Traceback (most recent call last):
  File "C:\Users\javacloudmc597\Documents\PythonLearning\Day12\app.py", line 169, in register
    db.session.commit()
  File "<string>", line 2, in commit
  File "c:\users\javacloudmc597\.virtualenvs\day12-bmnoo7rb\lib\site-packages\sqlalchemy\orm\session.py", line 1415, in commit
    self._transaction.commit(_to_root=self.future)
  File "c:\users\javacloudmc597\.virtualenvs\day12-bmnoo7rb\lib\site-packages\sqlalchemy\orm\session.py", line 829, in commit
    self._prepare_impl()
  File "c:\users\javacloudmc597\.virtualenvs\day12-bmnoo7rb\lib\site-packages\sqlalchemy\orm\session.py", line 808, in _prepare_impl
    self.session.flush()
  File "c:\users\javacloudmc597\.virtualenvs\day12-bmnoo7rb\lib\site-packages\sqlalchemy\orm\session.py", line 3233, in flush
    self._flush(objects)
  File "c:\users\javacloudmc597\.virtualenvs\day12-bmnoo7rb\lib\site-packages\sqlalchemy\orm\session.py", line 3373, in _flush
    transaction.rollback(_capture_exception=True)
  File "c:\users\javacloudmc597\.virtualenvs\day12-bmnoo7rb\lib\site-packages\sqlalchemy\util\langhelpers.py", line 70, in __exit__
    compat.raise_(
  File "c:\users\javacloudmc597\.virtualenvs\day12-bmnoo7rb\lib\site-packages\sqlalchemy\util\compat.py", line 198, in raise_
    raise exception
  File "c:\users\javacloudmc597\.virtualenvs\day12-bmnoo7rb\lib\site-packages\sqlalchemy\orm\session.py", line 3333, in _flush
    flush_context.execute()
  File "c:\users\javacloudmc597\.virtualenvs\day12-bmnoo7rb\lib\site-packages\sqlalchemy\orm\unitofwork.py", line 453, in execute
    rec.execute(self)
  File "c:\users\javacloudmc597\.virtualenvs\day12-bmnoo7rb\lib\site-packages\sqlalchemy\orm\unitofwork.py", line 627, in execute
    util.preloaded.orm_persistence.save_obj(
  File "c:\users\javacloudmc597\.virtualenvs\day12-bmnoo7rb\lib\site-packages\sqlalchemy\orm\persistence.py", line 242, in save_obj
    _emit_insert_statements(
  File "c:\users\javacloudmc597\.virtualenvs\day12-bmnoo7rb\lib\site-packages\sqlalchemy\orm\persistence.py", line 1219, in _emit_insert_statements
    result = connection._execute_20(
  File "c:\users\javacloudmc597\.virtualenvs\day12-bmnoo7rb\lib\site-packages\sqlalchemy\engine\base.py", line 1520, in _execute_20
    return meth(self, args_10style, kwargs_10style, execution_options)
  File "c:\users\javacloudmc597\.virtualenvs\day12-bmnoo7rb\lib\site-packages\sqlalchemy\sql\elements.py", line 313, in _execute_on_connection
    return connection._execute_clauseelement(
  File "c:\users\javacloudmc597\.virtualenvs\day12-bmnoo7rb\lib\site-packages\sqlalchemy\engine\base.py", line 1389, in _execute_clauseelement
    ret = self._execute_context(
  File "c:\users\javacloudmc597\.virtualenvs\day12-bmnoo7rb\lib\site-packages\sqlalchemy\engine\base.py", line 1614, in _execute_context
    self._handle_dbapi_exception(
  File "c:\users\javacloudmc597\.virtualenvs\day12-bmnoo7rb\lib\site-packages\sqlalchemy\engine\base.py", line 1929, in _handle_dbapi_exception
    util.raise_(
  File "c:\users\javacloudmc597\.virtualenvs\day12-bmnoo7rb\lib\site-packages\sqlalchemy\util\compat.py", line 198, in raise_
    raise exception
  File "c:\users\javacloudmc597\.virtualenvs\day12-bmnoo7rb\lib\site-packages\sqlalchemy\engine\base.py", line 1608, in _execute_context
    context = constructor(
  File "c:\users\javacloudmc597\.virtualenvs\day12-bmnoo7rb\lib\site-packages\sqlalchemy\engine\default.py", line 1011, in _init_compiled
    param = [
  File "c:\users\javacloudmc597\.virtualenvs\day12-bmnoo7rb\lib\site-packages\sqlalchemy\engine\default.py", line 1012, in <listcomp>
    processors[key](compiled_params[key])
sqlalchemy.exc.StatementError: (builtins.ValueError) could not convert string to float: 'dem2'
[SQL: INSERT INTO user (name, username, email, password, address, state, country, pan, "contactNumber", dob) VALUES (?, ?, ?, ?, ?, ?, ?, ?, ?, ?)]
[parameters: [{'username': 'dem3', 'address': 'dem2', 'state': 'dem2', 'country': 'dem2', 'pan': '69623267dema3', 'email': 'dem3@1google.com', 'contactNumber': '0897645390', 'name': 'dem3', 'dob': '30-Mar-2021', 'password': 'sha256$TTx0fj8r$cd23ed8ce4d5365a78386a8a8c485d37f7edad95ebba594eacc5c060bc52ac7e'}]]
2021-03-30 13:19:40,928- INFO -  _internal -  113 - 127.0.0.1 - - [30/Mar/2021 13:19:40] "[35m[1mPOST /cogbank/1.0/register/ HTTP/1.1[0m" 500 -
2021-03-30 13:19:40,969- ERROR -  _internal -  113 - Error on request:
Traceback (most recent call last):
  File "C:\Users\javacloudmc597\.virtualenvs\Day12-BmNoO7RB\Lib\site-packages\sqlalchemy\engine\base.py", line 1608, in _execute_context
    context = constructor(
  File "C:\Users\javacloudmc597\.virtualenvs\Day12-BmNoO7RB\Lib\site-packages\sqlalchemy\engine\default.py", line 1011, in _init_compiled
    param = [
  File "C:\Users\javacloudmc597\.virtualenvs\Day12-BmNoO7RB\Lib\site-packages\sqlalchemy\engine\default.py", line 1012, in <listcomp>
    processors[key](compiled_params[key])
ValueError: could not convert string to float: 'dem2'

The above exception was the direct cause of the following exception:

Traceback (most recent call last):
  File "C:\Users\javacloudmc597\Documents\PythonLearning\Day12\app.py", line 169, in register
    db.session.commit()
  File "<string>", line 2, in commit
    
  File "C:\Users\javacloudmc597\.virtualenvs\Day12-BmNoO7RB\Lib\site-packages\sqlalchemy\orm\session.py", line 1415, in commit
    self._transaction.commit(_to_root=self.future)
  File "C:\Users\javacloudmc597\.virtualenvs\Day12-BmNoO7RB\Lib\site-packages\sqlalchemy\orm\session.py", line 829, in commit
    self._prepare_impl()
  File "C:\Users\javacloudmc597\.virtualenvs\Day12-BmNoO7RB\Lib\site-packages\sqlalchemy\orm\session.py", line 808, in _prepare_impl
    self.session.flush()
  File "C:\Users\javacloudmc597\.virtualenvs\Day12-BmNoO7RB\Lib\site-packages\sqlalchemy\orm\session.py", line 3233, in flush
    self._flush(objects)
  File "C:\Users\javacloudmc597\.virtualenvs\Day12-BmNoO7RB\Lib\site-packages\sqlalchemy\orm\session.py", line 3373, in _flush
    transaction.rollback(_capture_exception=True)
  File "C:\Users\javacloudmc597\.virtualenvs\Day12-BmNoO7RB\Lib\site-packages\sqlalchemy\util\langhelpers.py", line 70, in __exit__
    compat.raise_(
  File "C:\Users\javacloudmc597\.virtualenvs\Day12-BmNoO7RB\Lib\site-packages\sqlalchemy\util\compat.py", line 198, in raise_
    raise exception
  File "C:\Users\javacloudmc597\.virtualenvs\Day12-BmNoO7RB\Lib\site-packages\sqlalchemy\orm\session.py", line 3333, in _flush
    flush_context.execute()
  File "C:\Users\javacloudmc597\.virtualenvs\Day12-BmNoO7RB\Lib\site-packages\sqlalchemy\orm\unitofwork.py", line 453, in execute
    rec.execute(self)
  File "C:\Users\javacloudmc597\.virtualenvs\Day12-BmNoO7RB\Lib\site-packages\sqlalchemy\orm\unitofwork.py", line 627, in execute
    util.preloaded.orm_persistence.save_obj(
  File "C:\Users\javacloudmc597\.virtualenvs\Day12-BmNoO7RB\Lib\site-packages\sqlalchemy\orm\persistence.py", line 242, in save_obj
    _emit_insert_statements(
  File "C:\Users\javacloudmc597\.virtualenvs\Day12-BmNoO7RB\Lib\site-packages\sqlalchemy\orm\persistence.py", line 1219, in _emit_insert_statements
    result = connection._execute_20(
  File "C:\Users\javacloudmc597\.virtualenvs\Day12-BmNoO7RB\Lib\site-packages\sqlalchemy\engine\base.py", line 1520, in _execute_20
    return meth(self, args_10style, kwargs_10style, execution_options)
  File "C:\Users\javacloudmc597\.virtualenvs\Day12-BmNoO7RB\Lib\site-packages\sqlalchemy\sql\elements.py", line 313, in _execute_on_connection
    return connection._execute_clauseelement(
  File "C:\Users\javacloudmc597\.virtualenvs\Day12-BmNoO7RB\Lib\site-packages\sqlalchemy\engine\base.py", line 1389, in _execute_clauseelement
    ret = self._execute_context(
  File "C:\Users\javacloudmc597\.virtualenvs\Day12-BmNoO7RB\Lib\site-packages\sqlalchemy\engine\base.py", line 1614, in _execute_context
    self._handle_dbapi_exception(
  File "C:\Users\javacloudmc597\.virtualenvs\Day12-BmNoO7RB\Lib\site-packages\sqlalchemy\engine\base.py", line 1929, in _handle_dbapi_exception
    util.raise_(
  File "C:\Users\javacloudmc597\.virtualenvs\Day12-BmNoO7RB\Lib\site-packages\sqlalchemy\util\compat.py", line 198, in raise_
    raise exception
  File "C:\Users\javacloudmc597\.virtualenvs\Day12-BmNoO7RB\Lib\site-packages\sqlalchemy\engine\base.py", line 1608, in _execute_context
    context = constructor(
  File "C:\Users\javacloudmc597\.virtualenvs\Day12-BmNoO7RB\Lib\site-packages\sqlalchemy\engine\default.py", line 1011, in _init_compiled
    param = [
  File "C:\Users\javacloudmc597\.virtualenvs\Day12-BmNoO7RB\Lib\site-packages\sqlalchemy\engine\default.py", line 1012, in <listcomp>
    processors[key](compiled_params[key])
sqlalchemy.exc.StatementError: (builtins.ValueError) could not convert string to float: 'dem2'
[SQL: INSERT INTO user (name, username, email, password, address, state, country, pan, "contactNumber", dob) VALUES (?, ?, ?, ?, ?, ?, ?, ?, ?, ?)]
[parameters: [{'username': 'dem3', 'address': 'dem2', 'state': 'dem2', 'country': 'dem2', 'pan': '69623267dema3', 'email': 'dem3@1google.com', 'contactNumber': '0897645390', 'name': 'dem3', 'dob': '30-Mar-2021', 'password': 'sha256$TTx0fj8r$cd23ed8ce4d5365a78386a8a8c485d37f7edad95ebba594eacc5c060bc52ac7e'}]]

During handling of the above exception, another exception occurred:

Traceback (most recent call last):
  File "C:\Users\javacloudmc597\.virtualenvs\Day12-BmNoO7RB\Lib\site-packages\werkzeug\serving.py", line 323, in run_wsgi
    execute(self.server.app)
  File "C:\Users\javacloudmc597\.virtualenvs\Day12-BmNoO7RB\Lib\site-packages\werkzeug\serving.py", line 312, in execute
    application_iter = app(environ, start_response)
  File "C:\Users\javacloudmc597\.virtualenvs\Day12-BmNoO7RB\Lib\site-packages\flask\app.py", line 2464, in __call__
    return self.wsgi_app(environ, start_response)
  File "C:\Users\javacloudmc597\.virtualenvs\Day12-BmNoO7RB\Lib\site-packages\flask\app.py", line 2450, in wsgi_app
    response = self.handle_exception(e)
  File "C:\Users\javacloudmc597\.virtualenvs\Day12-BmNoO7RB\Lib\site-packages\flask\app.py", line 1867, in handle_exception
    reraise(exc_type, exc_value, tb)
  File "C:\Users\javacloudmc597\.virtualenvs\Day12-BmNoO7RB\Lib\site-packages\flask\_compat.py", line 39, in reraise
    raise value
  File "C:\Users\javacloudmc597\.virtualenvs\Day12-BmNoO7RB\Lib\site-packages\flask\app.py", line 2447, in wsgi_app
    response = self.full_dispatch_request()
  File "C:\Users\javacloudmc597\.virtualenvs\Day12-BmNoO7RB\Lib\site-packages\flask\app.py", line 1952, in full_dispatch_request
    rv = self.handle_user_exception(e)
  File "C:\Users\javacloudmc597\.virtualenvs\Day12-BmNoO7RB\Lib\site-packages\flask\app.py", line 1821, in handle_user_exception
    reraise(exc_type, exc_value, tb)
  File "C:\Users\javacloudmc597\.virtualenvs\Day12-BmNoO7RB\Lib\site-packages\flask\_compat.py", line 39, in reraise
    raise value
  File "C:\Users\javacloudmc597\.virtualenvs\Day12-BmNoO7RB\Lib\site-packages\flask\app.py", line 1950, in full_dispatch_request
    rv = self.dispatch_request()
  File "C:\Users\javacloudmc597\.virtualenvs\Day12-BmNoO7RB\Lib\site-packages\flask\app.py", line 1936, in dispatch_request
    return self.view_functions[rule.endpoint](**req.view_args)
  File "C:\Users\javacloudmc597\Documents\PythonLearning\Day12\app.py", line 184, in register
    return jsonify({"Error":str(error.message)}),400
AttributeError: 'StatementError' object has no attribute 'message'
2021-03-30 13:20:47,929- INFO -  _internal -  113 -  * Running on http://127.0.0.1:5000/ (Press CTRL+C to quit)
2021-03-30 13:20:50,360- ERROR -  app -  183 - (builtins.ValueError) could not convert string to float: 'dem2'
[SQL: INSERT INTO user (name, username, email, password, address, state, country, pan, "contactNumber", dob) VALUES (?, ?, ?, ?, ?, ?, ?, ?, ?, ?)]
[parameters: [{'contactNumber': '0897645390', 'address': 'dem2', 'state': 'dem2', 'email': 'dem3@1google.com', 'country': 'dem2', 'name': 'dem3', 'password': 'sha256$DLMCN2KD$9e1c2fe7773cbc2981e5001b26ca63859f3c76b4ee29a204a736f5fa2114efb6', 'pan': '69623267dema3', 'dob': '30-Mar-2021', 'username': 'dem3'}]]
Traceback (most recent call last):
  File "c:\users\javacloudmc597\.virtualenvs\day12-bmnoo7rb\lib\site-packages\sqlalchemy\engine\base.py", line 1608, in _execute_context
    context = constructor(
  File "c:\users\javacloudmc597\.virtualenvs\day12-bmnoo7rb\lib\site-packages\sqlalchemy\engine\default.py", line 1011, in _init_compiled
    param = [
  File "c:\users\javacloudmc597\.virtualenvs\day12-bmnoo7rb\lib\site-packages\sqlalchemy\engine\default.py", line 1012, in <listcomp>
    processors[key](compiled_params[key])
ValueError: could not convert string to float: 'dem2'

The above exception was the direct cause of the following exception:

Traceback (most recent call last):
  File "C:\Users\javacloudmc597\Documents\PythonLearning\Day12\app.py", line 169, in register
    db.session.commit()
  File "<string>", line 2, in commit
  File "c:\users\javacloudmc597\.virtualenvs\day12-bmnoo7rb\lib\site-packages\sqlalchemy\orm\session.py", line 1415, in commit
    self._transaction.commit(_to_root=self.future)
  File "c:\users\javacloudmc597\.virtualenvs\day12-bmnoo7rb\lib\site-packages\sqlalchemy\orm\session.py", line 829, in commit
    self._prepare_impl()
  File "c:\users\javacloudmc597\.virtualenvs\day12-bmnoo7rb\lib\site-packages\sqlalchemy\orm\session.py", line 808, in _prepare_impl
    self.session.flush()
  File "c:\users\javacloudmc597\.virtualenvs\day12-bmnoo7rb\lib\site-packages\sqlalchemy\orm\session.py", line 3233, in flush
    self._flush(objects)
  File "c:\users\javacloudmc597\.virtualenvs\day12-bmnoo7rb\lib\site-packages\sqlalchemy\orm\session.py", line 3373, in _flush
    transaction.rollback(_capture_exception=True)
  File "c:\users\javacloudmc597\.virtualenvs\day12-bmnoo7rb\lib\site-packages\sqlalchemy\util\langhelpers.py", line 70, in __exit__
    compat.raise_(
  File "c:\users\javacloudmc597\.virtualenvs\day12-bmnoo7rb\lib\site-packages\sqlalchemy\util\compat.py", line 198, in raise_
    raise exception
  File "c:\users\javacloudmc597\.virtualenvs\day12-bmnoo7rb\lib\site-packages\sqlalchemy\orm\session.py", line 3333, in _flush
    flush_context.execute()
  File "c:\users\javacloudmc597\.virtualenvs\day12-bmnoo7rb\lib\site-packages\sqlalchemy\orm\unitofwork.py", line 453, in execute
    rec.execute(self)
  File "c:\users\javacloudmc597\.virtualenvs\day12-bmnoo7rb\lib\site-packages\sqlalchemy\orm\unitofwork.py", line 627, in execute
    util.preloaded.orm_persistence.save_obj(
  File "c:\users\javacloudmc597\.virtualenvs\day12-bmnoo7rb\lib\site-packages\sqlalchemy\orm\persistence.py", line 242, in save_obj
    _emit_insert_statements(
  File "c:\users\javacloudmc597\.virtualenvs\day12-bmnoo7rb\lib\site-packages\sqlalchemy\orm\persistence.py", line 1219, in _emit_insert_statements
    result = connection._execute_20(
  File "c:\users\javacloudmc597\.virtualenvs\day12-bmnoo7rb\lib\site-packages\sqlalchemy\engine\base.py", line 1520, in _execute_20
    return meth(self, args_10style, kwargs_10style, execution_options)
  File "c:\users\javacloudmc597\.virtualenvs\day12-bmnoo7rb\lib\site-packages\sqlalchemy\sql\elements.py", line 313, in _execute_on_connection
    return connection._execute_clauseelement(
  File "c:\users\javacloudmc597\.virtualenvs\day12-bmnoo7rb\lib\site-packages\sqlalchemy\engine\base.py", line 1389, in _execute_clauseelement
    ret = self._execute_context(
  File "c:\users\javacloudmc597\.virtualenvs\day12-bmnoo7rb\lib\site-packages\sqlalchemy\engine\base.py", line 1614, in _execute_context
    self._handle_dbapi_exception(
  File "c:\users\javacloudmc597\.virtualenvs\day12-bmnoo7rb\lib\site-packages\sqlalchemy\engine\base.py", line 1929, in _handle_dbapi_exception
    util.raise_(
  File "c:\users\javacloudmc597\.virtualenvs\day12-bmnoo7rb\lib\site-packages\sqlalchemy\util\compat.py", line 198, in raise_
    raise exception
  File "c:\users\javacloudmc597\.virtualenvs\day12-bmnoo7rb\lib\site-packages\sqlalchemy\engine\base.py", line 1608, in _execute_context
    context = constructor(
  File "c:\users\javacloudmc597\.virtualenvs\day12-bmnoo7rb\lib\site-packages\sqlalchemy\engine\default.py", line 1011, in _init_compiled
    param = [
  File "c:\users\javacloudmc597\.virtualenvs\day12-bmnoo7rb\lib\site-packages\sqlalchemy\engine\default.py", line 1012, in <listcomp>
    processors[key](compiled_params[key])
sqlalchemy.exc.StatementError: (builtins.ValueError) could not convert string to float: 'dem2'
[SQL: INSERT INTO user (name, username, email, password, address, state, country, pan, "contactNumber", dob) VALUES (?, ?, ?, ?, ?, ?, ?, ?, ?, ?)]
[parameters: [{'contactNumber': '0897645390', 'address': 'dem2', 'state': 'dem2', 'email': 'dem3@1google.com', 'country': 'dem2', 'name': 'dem3', 'password': 'sha256$DLMCN2KD$9e1c2fe7773cbc2981e5001b26ca63859f3c76b4ee29a204a736f5fa2114efb6', 'pan': '69623267dema3', 'dob': '30-Mar-2021', 'username': 'dem3'}]]
2021-03-30 13:20:50,370- INFO -  _internal -  113 - 127.0.0.1 - - [30/Mar/2021 13:20:50] "[31m[1mPOST /cogbank/1.0/register/ HTTP/1.1[0m" 400 -
2021-03-30 13:22:16,356- INFO -  _internal -  113 -  * Running on http://127.0.0.1:5000/ (Press CTRL+C to quit)
2021-03-30 13:22:18,676- ERROR -  app -  183 - (builtins.ValueError) could not convert string to float: 'dem2'
[SQL: INSERT INTO user (name, username, email, password, address, state, country, pan, "contactNumber", dob) VALUES (?, ?, ?, ?, ?, ?, ?, ?, ?, ?)]
[parameters: [{'country': 'dem2', 'name': 'dem3', 'email': 'dem3@1google.com', 'password': 'sha256$JznLy0XN$f135b9b6153eddfac511d2886a39c6e8ebb6476afb11a51647d0bc10740380c7', 'address': 'dem2', 'dob': '30-Mar-2021', 'contactNumber': '0897645390', 'state': 'dem2', 'pan': '69623267dema3', 'username': 'dem3'}]]
Traceback (most recent call last):
  File "c:\users\javacloudmc597\.virtualenvs\day12-bmnoo7rb\lib\site-packages\sqlalchemy\engine\base.py", line 1608, in _execute_context
    context = constructor(
  File "c:\users\javacloudmc597\.virtualenvs\day12-bmnoo7rb\lib\site-packages\sqlalchemy\engine\default.py", line 1011, in _init_compiled
    param = [
  File "c:\users\javacloudmc597\.virtualenvs\day12-bmnoo7rb\lib\site-packages\sqlalchemy\engine\default.py", line 1012, in <listcomp>
    processors[key](compiled_params[key])
ValueError: could not convert string to float: 'dem2'

The above exception was the direct cause of the following exception:

Traceback (most recent call last):
  File "C:\Users\javacloudmc597\Documents\PythonLearning\Day12\app.py", line 169, in register
    db.session.commit()
  File "<string>", line 2, in commit
  File "c:\users\javacloudmc597\.virtualenvs\day12-bmnoo7rb\lib\site-packages\sqlalchemy\orm\session.py", line 1415, in commit
    self._transaction.commit(_to_root=self.future)
  File "c:\users\javacloudmc597\.virtualenvs\day12-bmnoo7rb\lib\site-packages\sqlalchemy\orm\session.py", line 829, in commit
    self._prepare_impl()
  File "c:\users\javacloudmc597\.virtualenvs\day12-bmnoo7rb\lib\site-packages\sqlalchemy\orm\session.py", line 808, in _prepare_impl
    self.session.flush()
  File "c:\users\javacloudmc597\.virtualenvs\day12-bmnoo7rb\lib\site-packages\sqlalchemy\orm\session.py", line 3233, in flush
    self._flush(objects)
  File "c:\users\javacloudmc597\.virtualenvs\day12-bmnoo7rb\lib\site-packages\sqlalchemy\orm\session.py", line 3373, in _flush
    transaction.rollback(_capture_exception=True)
  File "c:\users\javacloudmc597\.virtualenvs\day12-bmnoo7rb\lib\site-packages\sqlalchemy\util\langhelpers.py", line 70, in __exit__
    compat.raise_(
  File "c:\users\javacloudmc597\.virtualenvs\day12-bmnoo7rb\lib\site-packages\sqlalchemy\util\compat.py", line 198, in raise_
    raise exception
  File "c:\users\javacloudmc597\.virtualenvs\day12-bmnoo7rb\lib\site-packages\sqlalchemy\orm\session.py", line 3333, in _flush
    flush_context.execute()
  File "c:\users\javacloudmc597\.virtualenvs\day12-bmnoo7rb\lib\site-packages\sqlalchemy\orm\unitofwork.py", line 453, in execute
    rec.execute(self)
  File "c:\users\javacloudmc597\.virtualenvs\day12-bmnoo7rb\lib\site-packages\sqlalchemy\orm\unitofwork.py", line 627, in execute
    util.preloaded.orm_persistence.save_obj(
  File "c:\users\javacloudmc597\.virtualenvs\day12-bmnoo7rb\lib\site-packages\sqlalchemy\orm\persistence.py", line 242, in save_obj
    _emit_insert_statements(
  File "c:\users\javacloudmc597\.virtualenvs\day12-bmnoo7rb\lib\site-packages\sqlalchemy\orm\persistence.py", line 1219, in _emit_insert_statements
    result = connection._execute_20(
  File "c:\users\javacloudmc597\.virtualenvs\day12-bmnoo7rb\lib\site-packages\sqlalchemy\engine\base.py", line 1520, in _execute_20
    return meth(self, args_10style, kwargs_10style, execution_options)
  File "c:\users\javacloudmc597\.virtualenvs\day12-bmnoo7rb\lib\site-packages\sqlalchemy\sql\elements.py", line 313, in _execute_on_connection
    return connection._execute_clauseelement(
  File "c:\users\javacloudmc597\.virtualenvs\day12-bmnoo7rb\lib\site-packages\sqlalchemy\engine\base.py", line 1389, in _execute_clauseelement
    ret = self._execute_context(
  File "c:\users\javacloudmc597\.virtualenvs\day12-bmnoo7rb\lib\site-packages\sqlalchemy\engine\base.py", line 1614, in _execute_context
    self._handle_dbapi_exception(
  File "c:\users\javacloudmc597\.virtualenvs\day12-bmnoo7rb\lib\site-packages\sqlalchemy\engine\base.py", line 1929, in _handle_dbapi_exception
    util.raise_(
  File "c:\users\javacloudmc597\.virtualenvs\day12-bmnoo7rb\lib\site-packages\sqlalchemy\util\compat.py", line 198, in raise_
    raise exception
  File "c:\users\javacloudmc597\.virtualenvs\day12-bmnoo7rb\lib\site-packages\sqlalchemy\engine\base.py", line 1608, in _execute_context
    context = constructor(
  File "c:\users\javacloudmc597\.virtualenvs\day12-bmnoo7rb\lib\site-packages\sqlalchemy\engine\default.py", line 1011, in _init_compiled
    param = [
  File "c:\users\javacloudmc597\.virtualenvs\day12-bmnoo7rb\lib\site-packages\sqlalchemy\engine\default.py", line 1012, in <listcomp>
    processors[key](compiled_params[key])
sqlalchemy.exc.StatementError: (builtins.ValueError) could not convert string to float: 'dem2'
[SQL: INSERT INTO user (name, username, email, password, address, state, country, pan, "contactNumber", dob) VALUES (?, ?, ?, ?, ?, ?, ?, ?, ?, ?)]
[parameters: [{'country': 'dem2', 'name': 'dem3', 'email': 'dem3@1google.com', 'password': 'sha256$JznLy0XN$f135b9b6153eddfac511d2886a39c6e8ebb6476afb11a51647d0bc10740380c7', 'address': 'dem2', 'dob': '30-Mar-2021', 'contactNumber': '0897645390', 'state': 'dem2', 'pan': '69623267dema3', 'username': 'dem3'}]]
2021-03-30 13:22:18,687- INFO -  _internal -  113 - 127.0.0.1 - - [30/Mar/2021 13:22:18] "[31m[1mPOST /cogbank/1.0/register/ HTTP/1.1[0m" 400 -
2021-03-30 13:23:50,224- INFO -  _internal -  113 -  * Running on http://127.0.0.1:5000/ (Press CTRL+C to quit)
2021-03-30 13:23:54,105- ERROR -  app -  183 - (builtins.ValueError) could not convert string to float: 'dem2'
[SQL: INSERT INTO user (name, username, email, password, address, state, country, pan, "contactNumber", dob) VALUES (?, ?, ?, ?, ?, ?, ?, ?, ?, ?)]
[parameters: [{'country': 'dem2', 'state': 'dem2', 'password': 'sha256$Z6sRj1Jn$7b61321df25577534c53a14c25666436bad4fd67a49e1aeabea63f672d1dc144', 'pan': '69623267dema3', 'dob': '30-Mar-2021', 'username': 'dem3', 'name': 'dem3', 'address': 'dem2', 'contactNumber': '0897645390', 'email': 'dem3@1google.com'}]]
Traceback (most recent call last):
  File "c:\users\javacloudmc597\.virtualenvs\day12-bmnoo7rb\lib\site-packages\sqlalchemy\engine\base.py", line 1608, in _execute_context
    context = constructor(
  File "c:\users\javacloudmc597\.virtualenvs\day12-bmnoo7rb\lib\site-packages\sqlalchemy\engine\default.py", line 1011, in _init_compiled
    param = [
  File "c:\users\javacloudmc597\.virtualenvs\day12-bmnoo7rb\lib\site-packages\sqlalchemy\engine\default.py", line 1012, in <listcomp>
    processors[key](compiled_params[key])
ValueError: could not convert string to float: 'dem2'

The above exception was the direct cause of the following exception:

Traceback (most recent call last):
  File "C:\Users\javacloudmc597\Documents\PythonLearning\Day12\app.py", line 169, in register
    db.session.commit()
  File "<string>", line 2, in commit
  File "c:\users\javacloudmc597\.virtualenvs\day12-bmnoo7rb\lib\site-packages\sqlalchemy\orm\session.py", line 1415, in commit
    self._transaction.commit(_to_root=self.future)
  File "c:\users\javacloudmc597\.virtualenvs\day12-bmnoo7rb\lib\site-packages\sqlalchemy\orm\session.py", line 829, in commit
    self._prepare_impl()
  File "c:\users\javacloudmc597\.virtualenvs\day12-bmnoo7rb\lib\site-packages\sqlalchemy\orm\session.py", line 808, in _prepare_impl
    self.session.flush()
  File "c:\users\javacloudmc597\.virtualenvs\day12-bmnoo7rb\lib\site-packages\sqlalchemy\orm\session.py", line 3233, in flush
    self._flush(objects)
  File "c:\users\javacloudmc597\.virtualenvs\day12-bmnoo7rb\lib\site-packages\sqlalchemy\orm\session.py", line 3373, in _flush
    transaction.rollback(_capture_exception=True)
  File "c:\users\javacloudmc597\.virtualenvs\day12-bmnoo7rb\lib\site-packages\sqlalchemy\util\langhelpers.py", line 70, in __exit__
    compat.raise_(
  File "c:\users\javacloudmc597\.virtualenvs\day12-bmnoo7rb\lib\site-packages\sqlalchemy\util\compat.py", line 198, in raise_
    raise exception
  File "c:\users\javacloudmc597\.virtualenvs\day12-bmnoo7rb\lib\site-packages\sqlalchemy\orm\session.py", line 3333, in _flush
    flush_context.execute()
  File "c:\users\javacloudmc597\.virtualenvs\day12-bmnoo7rb\lib\site-packages\sqlalchemy\orm\unitofwork.py", line 453, in execute
    rec.execute(self)
  File "c:\users\javacloudmc597\.virtualenvs\day12-bmnoo7rb\lib\site-packages\sqlalchemy\orm\unitofwork.py", line 627, in execute
    util.preloaded.orm_persistence.save_obj(
  File "c:\users\javacloudmc597\.virtualenvs\day12-bmnoo7rb\lib\site-packages\sqlalchemy\orm\persistence.py", line 242, in save_obj
    _emit_insert_statements(
  File "c:\users\javacloudmc597\.virtualenvs\day12-bmnoo7rb\lib\site-packages\sqlalchemy\orm\persistence.py", line 1219, in _emit_insert_statements
    result = connection._execute_20(
  File "c:\users\javacloudmc597\.virtualenvs\day12-bmnoo7rb\lib\site-packages\sqlalchemy\engine\base.py", line 1520, in _execute_20
    return meth(self, args_10style, kwargs_10style, execution_options)
  File "c:\users\javacloudmc597\.virtualenvs\day12-bmnoo7rb\lib\site-packages\sqlalchemy\sql\elements.py", line 313, in _execute_on_connection
    return connection._execute_clauseelement(
  File "c:\users\javacloudmc597\.virtualenvs\day12-bmnoo7rb\lib\site-packages\sqlalchemy\engine\base.py", line 1389, in _execute_clauseelement
    ret = self._execute_context(
  File "c:\users\javacloudmc597\.virtualenvs\day12-bmnoo7rb\lib\site-packages\sqlalchemy\engine\base.py", line 1614, in _execute_context
    self._handle_dbapi_exception(
  File "c:\users\javacloudmc597\.virtualenvs\day12-bmnoo7rb\lib\site-packages\sqlalchemy\engine\base.py", line 1929, in _handle_dbapi_exception
    util.raise_(
  File "c:\users\javacloudmc597\.virtualenvs\day12-bmnoo7rb\lib\site-packages\sqlalchemy\util\compat.py", line 198, in raise_
    raise exception
  File "c:\users\javacloudmc597\.virtualenvs\day12-bmnoo7rb\lib\site-packages\sqlalchemy\engine\base.py", line 1608, in _execute_context
    context = constructor(
  File "c:\users\javacloudmc597\.virtualenvs\day12-bmnoo7rb\lib\site-packages\sqlalchemy\engine\default.py", line 1011, in _init_compiled
    param = [
  File "c:\users\javacloudmc597\.virtualenvs\day12-bmnoo7rb\lib\site-packages\sqlalchemy\engine\default.py", line 1012, in <listcomp>
    processors[key](compiled_params[key])
sqlalchemy.exc.StatementError: (builtins.ValueError) could not convert string to float: 'dem2'
[SQL: INSERT INTO user (name, username, email, password, address, state, country, pan, "contactNumber", dob) VALUES (?, ?, ?, ?, ?, ?, ?, ?, ?, ?)]
[parameters: [{'country': 'dem2', 'state': 'dem2', 'password': 'sha256$Z6sRj1Jn$7b61321df25577534c53a14c25666436bad4fd67a49e1aeabea63f672d1dc144', 'pan': '69623267dema3', 'dob': '30-Mar-2021', 'username': 'dem3', 'name': 'dem3', 'address': 'dem2', 'contactNumber': '0897645390', 'email': 'dem3@1google.com'}]]
2021-03-30 13:23:54,272- INFO -  _internal -  113 - 127.0.0.1 - - [30/Mar/2021 13:23:54] "[35m[1mPOST /cogbank/1.0/register/ HTTP/1.1[0m" 500 -
2021-03-30 13:23:54,316- ERROR -  _internal -  113 - Error on request:
Traceback (most recent call last):
  File "C:\Users\javacloudmc597\.virtualenvs\Day12-BmNoO7RB\Lib\site-packages\sqlalchemy\engine\base.py", line 1608, in _execute_context
    context = constructor(
  File "C:\Users\javacloudmc597\.virtualenvs\Day12-BmNoO7RB\Lib\site-packages\sqlalchemy\engine\default.py", line 1011, in _init_compiled
    param = [
  File "C:\Users\javacloudmc597\.virtualenvs\Day12-BmNoO7RB\Lib\site-packages\sqlalchemy\engine\default.py", line 1012, in <listcomp>
    processors[key](compiled_params[key])
ValueError: could not convert string to float: 'dem2'

The above exception was the direct cause of the following exception:

Traceback (most recent call last):
  File "C:\Users\javacloudmc597\Documents\PythonLearning\Day12\app.py", line 169, in register
    db.session.commit()
  File "<string>", line 2, in commit
    
  File "C:\Users\javacloudmc597\.virtualenvs\Day12-BmNoO7RB\Lib\site-packages\sqlalchemy\orm\session.py", line 1415, in commit
    self._transaction.commit(_to_root=self.future)
  File "C:\Users\javacloudmc597\.virtualenvs\Day12-BmNoO7RB\Lib\site-packages\sqlalchemy\orm\session.py", line 829, in commit
    self._prepare_impl()
  File "C:\Users\javacloudmc597\.virtualenvs\Day12-BmNoO7RB\Lib\site-packages\sqlalchemy\orm\session.py", line 808, in _prepare_impl
    self.session.flush()
  File "C:\Users\javacloudmc597\.virtualenvs\Day12-BmNoO7RB\Lib\site-packages\sqlalchemy\orm\session.py", line 3233, in flush
    self._flush(objects)
  File "C:\Users\javacloudmc597\.virtualenvs\Day12-BmNoO7RB\Lib\site-packages\sqlalchemy\orm\session.py", line 3373, in _flush
    transaction.rollback(_capture_exception=True)
  File "C:\Users\javacloudmc597\.virtualenvs\Day12-BmNoO7RB\Lib\site-packages\sqlalchemy\util\langhelpers.py", line 70, in __exit__
    compat.raise_(
  File "C:\Users\javacloudmc597\.virtualenvs\Day12-BmNoO7RB\Lib\site-packages\sqlalchemy\util\compat.py", line 198, in raise_
    raise exception
  File "C:\Users\javacloudmc597\.virtualenvs\Day12-BmNoO7RB\Lib\site-packages\sqlalchemy\orm\session.py", line 3333, in _flush
    flush_context.execute()
  File "C:\Users\javacloudmc597\.virtualenvs\Day12-BmNoO7RB\Lib\site-packages\sqlalchemy\orm\unitofwork.py", line 453, in execute
    rec.execute(self)
  File "C:\Users\javacloudmc597\.virtualenvs\Day12-BmNoO7RB\Lib\site-packages\sqlalchemy\orm\unitofwork.py", line 627, in execute
    util.preloaded.orm_persistence.save_obj(
  File "C:\Users\javacloudmc597\.virtualenvs\Day12-BmNoO7RB\Lib\site-packages\sqlalchemy\orm\persistence.py", line 242, in save_obj
    _emit_insert_statements(
  File "C:\Users\javacloudmc597\.virtualenvs\Day12-BmNoO7RB\Lib\site-packages\sqlalchemy\orm\persistence.py", line 1219, in _emit_insert_statements
    result = connection._execute_20(
  File "C:\Users\javacloudmc597\.virtualenvs\Day12-BmNoO7RB\Lib\site-packages\sqlalchemy\engine\base.py", line 1520, in _execute_20
    return meth(self, args_10style, kwargs_10style, execution_options)
  File "C:\Users\javacloudmc597\.virtualenvs\Day12-BmNoO7RB\Lib\site-packages\sqlalchemy\sql\elements.py", line 313, in _execute_on_connection
    return connection._execute_clauseelement(
  File "C:\Users\javacloudmc597\.virtualenvs\Day12-BmNoO7RB\Lib\site-packages\sqlalchemy\engine\base.py", line 1389, in _execute_clauseelement
    ret = self._execute_context(
  File "C:\Users\javacloudmc597\.virtualenvs\Day12-BmNoO7RB\Lib\site-packages\sqlalchemy\engine\base.py", line 1614, in _execute_context
    self._handle_dbapi_exception(
  File "C:\Users\javacloudmc597\.virtualenvs\Day12-BmNoO7RB\Lib\site-packages\sqlalchemy\engine\base.py", line 1929, in _handle_dbapi_exception
    util.raise_(
  File "C:\Users\javacloudmc597\.virtualenvs\Day12-BmNoO7RB\Lib\site-packages\sqlalchemy\util\compat.py", line 198, in raise_
    raise exception
  File "C:\Users\javacloudmc597\.virtualenvs\Day12-BmNoO7RB\Lib\site-packages\sqlalchemy\engine\base.py", line 1608, in _execute_context
    context = constructor(
  File "C:\Users\javacloudmc597\.virtualenvs\Day12-BmNoO7RB\Lib\site-packages\sqlalchemy\engine\default.py", line 1011, in _init_compiled
    param = [
  File "C:\Users\javacloudmc597\.virtualenvs\Day12-BmNoO7RB\Lib\site-packages\sqlalchemy\engine\default.py", line 1012, in <listcomp>
    processors[key](compiled_params[key])
sqlalchemy.exc.StatementError: (builtins.ValueError) could not convert string to float: 'dem2'
[SQL: INSERT INTO user (name, username, email, password, address, state, country, pan, "contactNumber", dob) VALUES (?, ?, ?, ?, ?, ?, ?, ?, ?, ?)]
[parameters: [{'country': 'dem2', 'state': 'dem2', 'password': 'sha256$Z6sRj1Jn$7b61321df25577534c53a14c25666436bad4fd67a49e1aeabea63f672d1dc144', 'pan': '69623267dema3', 'dob': '30-Mar-2021', 'username': 'dem3', 'name': 'dem3', 'address': 'dem2', 'contactNumber': '0897645390', 'email': 'dem3@1google.com'}]]

During handling of the above exception, another exception occurred:

Traceback (most recent call last):
  File "C:\Users\javacloudmc597\.virtualenvs\Day12-BmNoO7RB\Lib\site-packages\werkzeug\serving.py", line 323, in run_wsgi
    execute(self.server.app)
  File "C:\Users\javacloudmc597\.virtualenvs\Day12-BmNoO7RB\Lib\site-packages\werkzeug\serving.py", line 312, in execute
    application_iter = app(environ, start_response)
  File "C:\Users\javacloudmc597\.virtualenvs\Day12-BmNoO7RB\Lib\site-packages\flask\app.py", line 2464, in __call__
    return self.wsgi_app(environ, start_response)
  File "C:\Users\javacloudmc597\.virtualenvs\Day12-BmNoO7RB\Lib\site-packages\flask\app.py", line 2450, in wsgi_app
    response = self.handle_exception(e)
  File "C:\Users\javacloudmc597\.virtualenvs\Day12-BmNoO7RB\Lib\site-packages\flask\app.py", line 1867, in handle_exception
    reraise(exc_type, exc_value, tb)
  File "C:\Users\javacloudmc597\.virtualenvs\Day12-BmNoO7RB\Lib\site-packages\flask\_compat.py", line 39, in reraise
    raise value
  File "C:\Users\javacloudmc597\.virtualenvs\Day12-BmNoO7RB\Lib\site-packages\flask\app.py", line 2447, in wsgi_app
    response = self.full_dispatch_request()
  File "C:\Users\javacloudmc597\.virtualenvs\Day12-BmNoO7RB\Lib\site-packages\flask\app.py", line 1952, in full_dispatch_request
    rv = self.handle_user_exception(e)
  File "C:\Users\javacloudmc597\.virtualenvs\Day12-BmNoO7RB\Lib\site-packages\flask\app.py", line 1821, in handle_user_exception
    reraise(exc_type, exc_value, tb)
  File "C:\Users\javacloudmc597\.virtualenvs\Day12-BmNoO7RB\Lib\site-packages\flask\_compat.py", line 39, in reraise
    raise value
  File "C:\Users\javacloudmc597\.virtualenvs\Day12-BmNoO7RB\Lib\site-packages\flask\app.py", line 1950, in full_dispatch_request
    rv = self.dispatch_request()
  File "C:\Users\javacloudmc597\.virtualenvs\Day12-BmNoO7RB\Lib\site-packages\flask\app.py", line 1936, in dispatch_request
    return self.view_functions[rule.endpoint](**req.view_args)
  File "C:\Users\javacloudmc597\Documents\PythonLearning\Day12\app.py", line 184, in register
    return jsonify({"Error":str(error.strerror)}),400
AttributeError: 'StatementError' object has no attribute 'strerror'
2021-03-30 13:25:57,711- INFO -  _internal -  113 -  * Running on http://127.0.0.1:5000/ (Press CTRL+C to quit)
2021-03-30 13:25:59,742- ERROR -  app -  183 - (builtins.ValueError) could not convert string to float: 'dem2'
[SQL: INSERT INTO user (name, username, email, password, address, state, country, pan, "contactNumber", dob) VALUES (?, ?, ?, ?, ?, ?, ?, ?, ?, ?)]
[parameters: [{'state': 'dem2', 'contactNumber': '0897645390', 'name': 'dem3', 'country': 'dem2', 'username': 'dem3', 'email': 'dem3@1google.com', 'address': 'dem2', 'password': 'sha256$Qaf45pxC$5a0c149a3a80fe6353bb3d6a74fd095f336c0aa3637caf772354ce4c64ce8e2a', 'dob': '30-Mar-2021', 'pan': '69623267dema3'}]]
Traceback (most recent call last):
  File "c:\users\javacloudmc597\.virtualenvs\day12-bmnoo7rb\lib\site-packages\sqlalchemy\engine\base.py", line 1608, in _execute_context
    context = constructor(
  File "c:\users\javacloudmc597\.virtualenvs\day12-bmnoo7rb\lib\site-packages\sqlalchemy\engine\default.py", line 1011, in _init_compiled
    param = [
  File "c:\users\javacloudmc597\.virtualenvs\day12-bmnoo7rb\lib\site-packages\sqlalchemy\engine\default.py", line 1012, in <listcomp>
    processors[key](compiled_params[key])
ValueError: could not convert string to float: 'dem2'

The above exception was the direct cause of the following exception:

Traceback (most recent call last):
  File "C:\Users\javacloudmc597\Documents\PythonLearning\Day12\app.py", line 169, in register
    db.session.commit()
  File "<string>", line 2, in commit
  File "c:\users\javacloudmc597\.virtualenvs\day12-bmnoo7rb\lib\site-packages\sqlalchemy\orm\session.py", line 1415, in commit
    self._transaction.commit(_to_root=self.future)
  File "c:\users\javacloudmc597\.virtualenvs\day12-bmnoo7rb\lib\site-packages\sqlalchemy\orm\session.py", line 829, in commit
    self._prepare_impl()
  File "c:\users\javacloudmc597\.virtualenvs\day12-bmnoo7rb\lib\site-packages\sqlalchemy\orm\session.py", line 808, in _prepare_impl
    self.session.flush()
  File "c:\users\javacloudmc597\.virtualenvs\day12-bmnoo7rb\lib\site-packages\sqlalchemy\orm\session.py", line 3233, in flush
    self._flush(objects)
  File "c:\users\javacloudmc597\.virtualenvs\day12-bmnoo7rb\lib\site-packages\sqlalchemy\orm\session.py", line 3373, in _flush
    transaction.rollback(_capture_exception=True)
  File "c:\users\javacloudmc597\.virtualenvs\day12-bmnoo7rb\lib\site-packages\sqlalchemy\util\langhelpers.py", line 70, in __exit__
    compat.raise_(
  File "c:\users\javacloudmc597\.virtualenvs\day12-bmnoo7rb\lib\site-packages\sqlalchemy\util\compat.py", line 198, in raise_
    raise exception
  File "c:\users\javacloudmc597\.virtualenvs\day12-bmnoo7rb\lib\site-packages\sqlalchemy\orm\session.py", line 3333, in _flush
    flush_context.execute()
  File "c:\users\javacloudmc597\.virtualenvs\day12-bmnoo7rb\lib\site-packages\sqlalchemy\orm\unitofwork.py", line 453, in execute
    rec.execute(self)
  File "c:\users\javacloudmc597\.virtualenvs\day12-bmnoo7rb\lib\site-packages\sqlalchemy\orm\unitofwork.py", line 627, in execute
    util.preloaded.orm_persistence.save_obj(
  File "c:\users\javacloudmc597\.virtualenvs\day12-bmnoo7rb\lib\site-packages\sqlalchemy\orm\persistence.py", line 242, in save_obj
    _emit_insert_statements(
  File "c:\users\javacloudmc597\.virtualenvs\day12-bmnoo7rb\lib\site-packages\sqlalchemy\orm\persistence.py", line 1219, in _emit_insert_statements
    result = connection._execute_20(
  File "c:\users\javacloudmc597\.virtualenvs\day12-bmnoo7rb\lib\site-packages\sqlalchemy\engine\base.py", line 1520, in _execute_20
    return meth(self, args_10style, kwargs_10style, execution_options)
  File "c:\users\javacloudmc597\.virtualenvs\day12-bmnoo7rb\lib\site-packages\sqlalchemy\sql\elements.py", line 313, in _execute_on_connection
    return connection._execute_clauseelement(
  File "c:\users\javacloudmc597\.virtualenvs\day12-bmnoo7rb\lib\site-packages\sqlalchemy\engine\base.py", line 1389, in _execute_clauseelement
    ret = self._execute_context(
  File "c:\users\javacloudmc597\.virtualenvs\day12-bmnoo7rb\lib\site-packages\sqlalchemy\engine\base.py", line 1614, in _execute_context
    self._handle_dbapi_exception(
  File "c:\users\javacloudmc597\.virtualenvs\day12-bmnoo7rb\lib\site-packages\sqlalchemy\engine\base.py", line 1929, in _handle_dbapi_exception
    util.raise_(
  File "c:\users\javacloudmc597\.virtualenvs\day12-bmnoo7rb\lib\site-packages\sqlalchemy\util\compat.py", line 198, in raise_
    raise exception
  File "c:\users\javacloudmc597\.virtualenvs\day12-bmnoo7rb\lib\site-packages\sqlalchemy\engine\base.py", line 1608, in _execute_context
    context = constructor(
  File "c:\users\javacloudmc597\.virtualenvs\day12-bmnoo7rb\lib\site-packages\sqlalchemy\engine\default.py", line 1011, in _init_compiled
    param = [
  File "c:\users\javacloudmc597\.virtualenvs\day12-bmnoo7rb\lib\site-packages\sqlalchemy\engine\default.py", line 1012, in <listcomp>
    processors[key](compiled_params[key])
sqlalchemy.exc.StatementError: (builtins.ValueError) could not convert string to float: 'dem2'
[SQL: INSERT INTO user (name, username, email, password, address, state, country, pan, "contactNumber", dob) VALUES (?, ?, ?, ?, ?, ?, ?, ?, ?, ?)]
[parameters: [{'state': 'dem2', 'contactNumber': '0897645390', 'name': 'dem3', 'country': 'dem2', 'username': 'dem3', 'email': 'dem3@1google.com', 'address': 'dem2', 'password': 'sha256$Qaf45pxC$5a0c149a3a80fe6353bb3d6a74fd095f336c0aa3637caf772354ce4c64ce8e2a', 'dob': '30-Mar-2021', 'pan': '69623267dema3'}]]
2021-03-30 13:25:59,752- INFO -  _internal -  113 - 127.0.0.1 - - [30/Mar/2021 13:25:59] "[31m[1mPOST /cogbank/1.0/register/ HTTP/1.1[0m" 400 -
2021-03-30 13:27:05,970- INFO -  _internal -  113 -  * Running on http://127.0.0.1:5000/ (Press CTRL+C to quit)
2021-03-30 13:27:08,457- ERROR -  app -  183 - (builtins.ValueError) could not convert string to float: 'dem2'
[SQL: INSERT INTO user (name, username, email, password, address, state, country, pan, "contactNumber", dob) VALUES (?, ?, ?, ?, ?, ?, ?, ?, ?, ?)]
[parameters: [{'name': 'dem3', 'password': 'sha256$3qIwXE2T$d363a1c8b42d6ed4eaa58fd6ffa7591e653985f74f9fa5e314b5cf6c7b189c88', 'pan': '69623267dema3', 'username': 'dem3', 'dob': '30-Mar-2021', 'contactNumber': '0897645390', 'state': 'dem2', 'email': 'dem3@1google.com', 'country': 'dem2', 'address': 'dem2'}]]
Traceback (most recent call last):
  File "c:\users\javacloudmc597\.virtualenvs\day12-bmnoo7rb\lib\site-packages\sqlalchemy\engine\base.py", line 1608, in _execute_context
    context = constructor(
  File "c:\users\javacloudmc597\.virtualenvs\day12-bmnoo7rb\lib\site-packages\sqlalchemy\engine\default.py", line 1011, in _init_compiled
    param = [
  File "c:\users\javacloudmc597\.virtualenvs\day12-bmnoo7rb\lib\site-packages\sqlalchemy\engine\default.py", line 1012, in <listcomp>
    processors[key](compiled_params[key])
ValueError: could not convert string to float: 'dem2'

The above exception was the direct cause of the following exception:

Traceback (most recent call last):
  File "C:\Users\javacloudmc597\Documents\PythonLearning\Day12\app.py", line 169, in register
    db.session.commit()
  File "<string>", line 2, in commit
  File "c:\users\javacloudmc597\.virtualenvs\day12-bmnoo7rb\lib\site-packages\sqlalchemy\orm\session.py", line 1415, in commit
    self._transaction.commit(_to_root=self.future)
  File "c:\users\javacloudmc597\.virtualenvs\day12-bmnoo7rb\lib\site-packages\sqlalchemy\orm\session.py", line 829, in commit
    self._prepare_impl()
  File "c:\users\javacloudmc597\.virtualenvs\day12-bmnoo7rb\lib\site-packages\sqlalchemy\orm\session.py", line 808, in _prepare_impl
    self.session.flush()
  File "c:\users\javacloudmc597\.virtualenvs\day12-bmnoo7rb\lib\site-packages\sqlalchemy\orm\session.py", line 3233, in flush
    self._flush(objects)
  File "c:\users\javacloudmc597\.virtualenvs\day12-bmnoo7rb\lib\site-packages\sqlalchemy\orm\session.py", line 3373, in _flush
    transaction.rollback(_capture_exception=True)
  File "c:\users\javacloudmc597\.virtualenvs\day12-bmnoo7rb\lib\site-packages\sqlalchemy\util\langhelpers.py", line 70, in __exit__
    compat.raise_(
  File "c:\users\javacloudmc597\.virtualenvs\day12-bmnoo7rb\lib\site-packages\sqlalchemy\util\compat.py", line 198, in raise_
    raise exception
  File "c:\users\javacloudmc597\.virtualenvs\day12-bmnoo7rb\lib\site-packages\sqlalchemy\orm\session.py", line 3333, in _flush
    flush_context.execute()
  File "c:\users\javacloudmc597\.virtualenvs\day12-bmnoo7rb\lib\site-packages\sqlalchemy\orm\unitofwork.py", line 453, in execute
    rec.execute(self)
  File "c:\users\javacloudmc597\.virtualenvs\day12-bmnoo7rb\lib\site-packages\sqlalchemy\orm\unitofwork.py", line 627, in execute
    util.preloaded.orm_persistence.save_obj(
  File "c:\users\javacloudmc597\.virtualenvs\day12-bmnoo7rb\lib\site-packages\sqlalchemy\orm\persistence.py", line 242, in save_obj
    _emit_insert_statements(
  File "c:\users\javacloudmc597\.virtualenvs\day12-bmnoo7rb\lib\site-packages\sqlalchemy\orm\persistence.py", line 1219, in _emit_insert_statements
    result = connection._execute_20(
  File "c:\users\javacloudmc597\.virtualenvs\day12-bmnoo7rb\lib\site-packages\sqlalchemy\engine\base.py", line 1520, in _execute_20
    return meth(self, args_10style, kwargs_10style, execution_options)
  File "c:\users\javacloudmc597\.virtualenvs\day12-bmnoo7rb\lib\site-packages\sqlalchemy\sql\elements.py", line 313, in _execute_on_connection
    return connection._execute_clauseelement(
  File "c:\users\javacloudmc597\.virtualenvs\day12-bmnoo7rb\lib\site-packages\sqlalchemy\engine\base.py", line 1389, in _execute_clauseelement
    ret = self._execute_context(
  File "c:\users\javacloudmc597\.virtualenvs\day12-bmnoo7rb\lib\site-packages\sqlalchemy\engine\base.py", line 1614, in _execute_context
    self._handle_dbapi_exception(
  File "c:\users\javacloudmc597\.virtualenvs\day12-bmnoo7rb\lib\site-packages\sqlalchemy\engine\base.py", line 1929, in _handle_dbapi_exception
    util.raise_(
  File "c:\users\javacloudmc597\.virtualenvs\day12-bmnoo7rb\lib\site-packages\sqlalchemy\util\compat.py", line 198, in raise_
    raise exception
  File "c:\users\javacloudmc597\.virtualenvs\day12-bmnoo7rb\lib\site-packages\sqlalchemy\engine\base.py", line 1608, in _execute_context
    context = constructor(
  File "c:\users\javacloudmc597\.virtualenvs\day12-bmnoo7rb\lib\site-packages\sqlalchemy\engine\default.py", line 1011, in _init_compiled
    param = [
  File "c:\users\javacloudmc597\.virtualenvs\day12-bmnoo7rb\lib\site-packages\sqlalchemy\engine\default.py", line 1012, in <listcomp>
    processors[key](compiled_params[key])
sqlalchemy.exc.StatementError: (builtins.ValueError) could not convert string to float: 'dem2'
[SQL: INSERT INTO user (name, username, email, password, address, state, country, pan, "contactNumber", dob) VALUES (?, ?, ?, ?, ?, ?, ?, ?, ?, ?)]
[parameters: [{'name': 'dem3', 'password': 'sha256$3qIwXE2T$d363a1c8b42d6ed4eaa58fd6ffa7591e653985f74f9fa5e314b5cf6c7b189c88', 'pan': '69623267dema3', 'username': 'dem3', 'dob': '30-Mar-2021', 'contactNumber': '0897645390', 'state': 'dem2', 'email': 'dem3@1google.com', 'country': 'dem2', 'address': 'dem2'}]]
2021-03-30 13:27:08,646- INFO -  _internal -  113 - 127.0.0.1 - - [30/Mar/2021 13:27:08] "[35m[1mPOST /cogbank/1.0/register/ HTTP/1.1[0m" 500 -
2021-03-30 13:27:08,685- ERROR -  _internal -  113 - Error on request:
Traceback (most recent call last):
  File "C:\Users\javacloudmc597\.virtualenvs\Day12-BmNoO7RB\Lib\site-packages\sqlalchemy\engine\base.py", line 1608, in _execute_context
    context = constructor(
  File "C:\Users\javacloudmc597\.virtualenvs\Day12-BmNoO7RB\Lib\site-packages\sqlalchemy\engine\default.py", line 1011, in _init_compiled
    param = [
  File "C:\Users\javacloudmc597\.virtualenvs\Day12-BmNoO7RB\Lib\site-packages\sqlalchemy\engine\default.py", line 1012, in <listcomp>
    processors[key](compiled_params[key])
ValueError: could not convert string to float: 'dem2'

The above exception was the direct cause of the following exception:

Traceback (most recent call last):
  File "C:\Users\javacloudmc597\Documents\PythonLearning\Day12\app.py", line 169, in register
    db.session.commit()
  File "<string>", line 2, in commit
    
  File "C:\Users\javacloudmc597\.virtualenvs\Day12-BmNoO7RB\Lib\site-packages\sqlalchemy\orm\session.py", line 1415, in commit
    self._transaction.commit(_to_root=self.future)
  File "C:\Users\javacloudmc597\.virtualenvs\Day12-BmNoO7RB\Lib\site-packages\sqlalchemy\orm\session.py", line 829, in commit
    self._prepare_impl()
  File "C:\Users\javacloudmc597\.virtualenvs\Day12-BmNoO7RB\Lib\site-packages\sqlalchemy\orm\session.py", line 808, in _prepare_impl
    self.session.flush()
  File "C:\Users\javacloudmc597\.virtualenvs\Day12-BmNoO7RB\Lib\site-packages\sqlalchemy\orm\session.py", line 3233, in flush
    self._flush(objects)
  File "C:\Users\javacloudmc597\.virtualenvs\Day12-BmNoO7RB\Lib\site-packages\sqlalchemy\orm\session.py", line 3373, in _flush
    transaction.rollback(_capture_exception=True)
  File "C:\Users\javacloudmc597\.virtualenvs\Day12-BmNoO7RB\Lib\site-packages\sqlalchemy\util\langhelpers.py", line 70, in __exit__
    compat.raise_(
  File "C:\Users\javacloudmc597\.virtualenvs\Day12-BmNoO7RB\Lib\site-packages\sqlalchemy\util\compat.py", line 198, in raise_
    raise exception
  File "C:\Users\javacloudmc597\.virtualenvs\Day12-BmNoO7RB\Lib\site-packages\sqlalchemy\orm\session.py", line 3333, in _flush
    flush_context.execute()
  File "C:\Users\javacloudmc597\.virtualenvs\Day12-BmNoO7RB\Lib\site-packages\sqlalchemy\orm\unitofwork.py", line 453, in execute
    rec.execute(self)
  File "C:\Users\javacloudmc597\.virtualenvs\Day12-BmNoO7RB\Lib\site-packages\sqlalchemy\orm\unitofwork.py", line 627, in execute
    util.preloaded.orm_persistence.save_obj(
  File "C:\Users\javacloudmc597\.virtualenvs\Day12-BmNoO7RB\Lib\site-packages\sqlalchemy\orm\persistence.py", line 242, in save_obj
    _emit_insert_statements(
  File "C:\Users\javacloudmc597\.virtualenvs\Day12-BmNoO7RB\Lib\site-packages\sqlalchemy\orm\persistence.py", line 1219, in _emit_insert_statements
    result = connection._execute_20(
  File "C:\Users\javacloudmc597\.virtualenvs\Day12-BmNoO7RB\Lib\site-packages\sqlalchemy\engine\base.py", line 1520, in _execute_20
    return meth(self, args_10style, kwargs_10style, execution_options)
  File "C:\Users\javacloudmc597\.virtualenvs\Day12-BmNoO7RB\Lib\site-packages\sqlalchemy\sql\elements.py", line 313, in _execute_on_connection
    return connection._execute_clauseelement(
  File "C:\Users\javacloudmc597\.virtualenvs\Day12-BmNoO7RB\Lib\site-packages\sqlalchemy\engine\base.py", line 1389, in _execute_clauseelement
    ret = self._execute_context(
  File "C:\Users\javacloudmc597\.virtualenvs\Day12-BmNoO7RB\Lib\site-packages\sqlalchemy\engine\base.py", line 1614, in _execute_context
    self._handle_dbapi_exception(
  File "C:\Users\javacloudmc597\.virtualenvs\Day12-BmNoO7RB\Lib\site-packages\sqlalchemy\engine\base.py", line 1929, in _handle_dbapi_exception
    util.raise_(
  File "C:\Users\javacloudmc597\.virtualenvs\Day12-BmNoO7RB\Lib\site-packages\sqlalchemy\util\compat.py", line 198, in raise_
    raise exception
  File "C:\Users\javacloudmc597\.virtualenvs\Day12-BmNoO7RB\Lib\site-packages\sqlalchemy\engine\base.py", line 1608, in _execute_context
    context = constructor(
  File "C:\Users\javacloudmc597\.virtualenvs\Day12-BmNoO7RB\Lib\site-packages\sqlalchemy\engine\default.py", line 1011, in _init_compiled
    param = [
  File "C:\Users\javacloudmc597\.virtualenvs\Day12-BmNoO7RB\Lib\site-packages\sqlalchemy\engine\default.py", line 1012, in <listcomp>
    processors[key](compiled_params[key])
sqlalchemy.exc.StatementError: (builtins.ValueError) could not convert string to float: 'dem2'
[SQL: INSERT INTO user (name, username, email, password, address, state, country, pan, "contactNumber", dob) VALUES (?, ?, ?, ?, ?, ?, ?, ?, ?, ?)]
[parameters: [{'name': 'dem3', 'password': 'sha256$3qIwXE2T$d363a1c8b42d6ed4eaa58fd6ffa7591e653985f74f9fa5e314b5cf6c7b189c88', 'pan': '69623267dema3', 'username': 'dem3', 'dob': '30-Mar-2021', 'contactNumber': '0897645390', 'state': 'dem2', 'email': 'dem3@1google.com', 'country': 'dem2', 'address': 'dem2'}]]

During handling of the above exception, another exception occurred:

Traceback (most recent call last):
  File "C:\Users\javacloudmc597\.virtualenvs\Day12-BmNoO7RB\Lib\site-packages\werkzeug\serving.py", line 323, in run_wsgi
    execute(self.server.app)
  File "C:\Users\javacloudmc597\.virtualenvs\Day12-BmNoO7RB\Lib\site-packages\werkzeug\serving.py", line 312, in execute
    application_iter = app(environ, start_response)
  File "C:\Users\javacloudmc597\.virtualenvs\Day12-BmNoO7RB\Lib\site-packages\flask\app.py", line 2464, in __call__
    return self.wsgi_app(environ, start_response)
  File "C:\Users\javacloudmc597\.virtualenvs\Day12-BmNoO7RB\Lib\site-packages\flask\app.py", line 2450, in wsgi_app
    response = self.handle_exception(e)
  File "C:\Users\javacloudmc597\.virtualenvs\Day12-BmNoO7RB\Lib\site-packages\flask\app.py", line 1867, in handle_exception
    reraise(exc_type, exc_value, tb)
  File "C:\Users\javacloudmc597\.virtualenvs\Day12-BmNoO7RB\Lib\site-packages\flask\_compat.py", line 39, in reraise
    raise value
  File "C:\Users\javacloudmc597\.virtualenvs\Day12-BmNoO7RB\Lib\site-packages\flask\app.py", line 2447, in wsgi_app
    response = self.full_dispatch_request()
  File "C:\Users\javacloudmc597\.virtualenvs\Day12-BmNoO7RB\Lib\site-packages\flask\app.py", line 1952, in full_dispatch_request
    rv = self.handle_user_exception(e)
  File "C:\Users\javacloudmc597\.virtualenvs\Day12-BmNoO7RB\Lib\site-packages\flask\app.py", line 1821, in handle_user_exception
    reraise(exc_type, exc_value, tb)
  File "C:\Users\javacloudmc597\.virtualenvs\Day12-BmNoO7RB\Lib\site-packages\flask\_compat.py", line 39, in reraise
    raise value
  File "C:\Users\javacloudmc597\.virtualenvs\Day12-BmNoO7RB\Lib\site-packages\flask\app.py", line 1950, in full_dispatch_request
    rv = self.dispatch_request()
  File "C:\Users\javacloudmc597\.virtualenvs\Day12-BmNoO7RB\Lib\site-packages\flask\app.py", line 1936, in dispatch_request
    return self.view_functions[rule.endpoint](**req.view_args)
  File "C:\Users\javacloudmc597\Documents\PythonLearning\Day12\app.py", line 184, in register
    return jsonify({"Error":__str__(error)}),400
NameError: name '__str__' is not defined
2021-03-30 13:31:12,704- INFO -  _internal -  113 -  * Running on http://127.0.0.1:5000/ (Press CTRL+C to quit)
2021-03-30 13:31:17,633- ERROR -  app -  368 - (sqlite3.IntegrityError) UNIQUE constraint failed: loan.username
[SQL: INSERT INTO loan (username, "LoanType", "LoanAmount", "Interest", "Date", "Duration") VALUES (?, ?, ?, ?, ?, ?)]
[parameters: ('dema', 'Fixed', 100, 2, '2021-03-19', '1 month')]
(Background on this error at: http://sqlalche.me/e/14/gkpj)
Traceback (most recent call last):
  File "c:\users\javacloudmc597\.virtualenvs\day12-bmnoo7rb\lib\site-packages\sqlalchemy\engine\base.py", line 1705, in _execute_context
    self.dialect.do_execute(
  File "c:\users\javacloudmc597\.virtualenvs\day12-bmnoo7rb\lib\site-packages\sqlalchemy\engine\default.py", line 681, in do_execute
    cursor.execute(statement, parameters)
sqlite3.IntegrityError: UNIQUE constraint failed: loan.username

The above exception was the direct cause of the following exception:

Traceback (most recent call last):
  File "C:\Users\javacloudmc597\Documents\PythonLearning\Day12\app.py", line 347, in applyLoan
    db.session.commit()
  File "<string>", line 2, in commit
  File "c:\users\javacloudmc597\.virtualenvs\day12-bmnoo7rb\lib\site-packages\sqlalchemy\orm\session.py", line 1415, in commit
    self._transaction.commit(_to_root=self.future)
  File "c:\users\javacloudmc597\.virtualenvs\day12-bmnoo7rb\lib\site-packages\sqlalchemy\orm\session.py", line 829, in commit
    self._prepare_impl()
  File "c:\users\javacloudmc597\.virtualenvs\day12-bmnoo7rb\lib\site-packages\sqlalchemy\orm\session.py", line 808, in _prepare_impl
    self.session.flush()
  File "c:\users\javacloudmc597\.virtualenvs\day12-bmnoo7rb\lib\site-packages\sqlalchemy\orm\session.py", line 3233, in flush
    self._flush(objects)
  File "c:\users\javacloudmc597\.virtualenvs\day12-bmnoo7rb\lib\site-packages\sqlalchemy\orm\session.py", line 3373, in _flush
    transaction.rollback(_capture_exception=True)
  File "c:\users\javacloudmc597\.virtualenvs\day12-bmnoo7rb\lib\site-packages\sqlalchemy\util\langhelpers.py", line 70, in __exit__
    compat.raise_(
  File "c:\users\javacloudmc597\.virtualenvs\day12-bmnoo7rb\lib\site-packages\sqlalchemy\util\compat.py", line 198, in raise_
    raise exception
  File "c:\users\javacloudmc597\.virtualenvs\day12-bmnoo7rb\lib\site-packages\sqlalchemy\orm\session.py", line 3333, in _flush
    flush_context.execute()
  File "c:\users\javacloudmc597\.virtualenvs\day12-bmnoo7rb\lib\site-packages\sqlalchemy\orm\unitofwork.py", line 453, in execute
    rec.execute(self)
  File "c:\users\javacloudmc597\.virtualenvs\day12-bmnoo7rb\lib\site-packages\sqlalchemy\orm\unitofwork.py", line 627, in execute
    util.preloaded.orm_persistence.save_obj(
  File "c:\users\javacloudmc597\.virtualenvs\day12-bmnoo7rb\lib\site-packages\sqlalchemy\orm\persistence.py", line 242, in save_obj
    _emit_insert_statements(
  File "c:\users\javacloudmc597\.virtualenvs\day12-bmnoo7rb\lib\site-packages\sqlalchemy\orm\persistence.py", line 1219, in _emit_insert_statements
    result = connection._execute_20(
  File "c:\users\javacloudmc597\.virtualenvs\day12-bmnoo7rb\lib\site-packages\sqlalchemy\engine\base.py", line 1520, in _execute_20
    return meth(self, args_10style, kwargs_10style, execution_options)
  File "c:\users\javacloudmc597\.virtualenvs\day12-bmnoo7rb\lib\site-packages\sqlalchemy\sql\elements.py", line 313, in _execute_on_connection
    return connection._execute_clauseelement(
  File "c:\users\javacloudmc597\.virtualenvs\day12-bmnoo7rb\lib\site-packages\sqlalchemy\engine\base.py", line 1389, in _execute_clauseelement
    ret = self._execute_context(
  File "c:\users\javacloudmc597\.virtualenvs\day12-bmnoo7rb\lib\site-packages\sqlalchemy\engine\base.py", line 1748, in _execute_context
    self._handle_dbapi_exception(
  File "c:\users\javacloudmc597\.virtualenvs\day12-bmnoo7rb\lib\site-packages\sqlalchemy\engine\base.py", line 1929, in _handle_dbapi_exception
    util.raise_(
  File "c:\users\javacloudmc597\.virtualenvs\day12-bmnoo7rb\lib\site-packages\sqlalchemy\util\compat.py", line 198, in raise_
    raise exception
  File "c:\users\javacloudmc597\.virtualenvs\day12-bmnoo7rb\lib\site-packages\sqlalchemy\engine\base.py", line 1705, in _execute_context
    self.dialect.do_execute(
  File "c:\users\javacloudmc597\.virtualenvs\day12-bmnoo7rb\lib\site-packages\sqlalchemy\engine\default.py", line 681, in do_execute
    cursor.execute(statement, parameters)
sqlalchemy.exc.IntegrityError: (sqlite3.IntegrityError) UNIQUE constraint failed: loan.username
[SQL: INSERT INTO loan (username, "LoanType", "LoanAmount", "Interest", "Date", "Duration") VALUES (?, ?, ?, ?, ?, ?)]
[parameters: ('dema', 'Fixed', 100, 2, '2021-03-19', '1 month')]
(Background on this error at: http://sqlalche.me/e/14/gkpj)
2021-03-30 13:31:17,642- INFO -  _internal -  113 - 127.0.0.1 - - [30/Mar/2021 13:31:17] "[31m[1mPOST /cogbank/1.0/applyLoan/ HTTP/1.1[0m" 400 -
2021-03-30 14:32:31,388- INFO -  _internal -  113 - 127.0.0.1 - - [30/Mar/2021 14:32:31] "[33mGET /cogbank/1.0/getCustomer/ HTTP/1.1[0m" 404 -
2021-03-30 14:32:42,747- INFO -  _internal -  113 - 127.0.0.1 - - [30/Mar/2021 14:32:42] "[37mGET /cogbank/1.0/getCustomer/dema HTTP/1.1[0m" 200 -
2021-03-30 14:32:54,253- ERROR -  app -  304 - {'Status': 'The user is not registered'}
2021-03-30 14:32:54,254- INFO -  _internal -  113 - 127.0.0.1 - - [30/Mar/2021 14:32:54] "[33mGET /cogbank/1.0/getCustomer/dem HTTP/1.1[0m" 404 -
2021-03-30 14:42:15,159- INFO -  _internal -  113 - 127.0.0.1 - - [30/Mar/2021 14:42:15] "[37mGET /cogbank/1.0/logout/abc HTTP/1.1[0m" 200 -
2021-03-30 14:42:42,714- INFO -  _internal -  113 - 127.0.0.1 - - [30/Mar/2021 14:42:42] "[37mGET /cogbank/1.0/logout/dema HTTP/1.1[0m" 200 -
2021-03-30 14:44:08,485- INFO -  _internal -  113 - 127.0.0.1 - - [30/Mar/2021 14:44:08] "[37mGET /cogbank/1.0/getLoan/demasa HTTP/1.1[0m" 200 -
2021-03-30 14:44:20,717- INFO -  _internal -  113 - 127.0.0.1 - - [30/Mar/2021 14:44:20] "[37mPOST /cogbank/1.0/login/ HTTP/1.1[0m" 200 -
2021-03-30 14:44:24,099- ERROR -  app -  388 - User demasa not found. Please register
2021-03-30 14:44:24,099- INFO -  _internal -  113 - 127.0.0.1 - - [30/Mar/2021 14:44:24] "[37mGET /cogbank/1.0/getLoan/demasa HTTP/1.1[0m" 202 -
2021-03-30 14:44:39,552- INFO -  _internal -  113 - 127.0.0.1 - - [30/Mar/2021 14:44:39] "[37mGET /cogbank/1.0/getLoan/dema HTTP/1.1[0m" 200 -
2021-03-30 14:44:58,173- INFO -  _internal -  113 - 127.0.0.1 - - [30/Mar/2021 14:44:58] "[37mGET /cogbank/1.0/getLoan/irf HTTP/1.1[0m" 200 -
2021-03-30 14:45:46,550- INFO -  _internal -  113 - 127.0.0.1 - - [30/Mar/2021 14:45:46] "[37mGET /cogbank/1.0/logout/irf HTTP/1.1[0m" 200 -
2021-03-30 14:46:18,920- INFO -  _internal -  113 -  * Running on http://127.0.0.1:5000/ (Press CTRL+C to quit)
2021-03-30 14:46:28,305- ERROR -  app -  397 - name 'username' is not defined
Traceback (most recent call last):
  File "C:\Users\javacloudmc597\Documents\PythonLearning\Day12\app.py", line 374, in getLoan
    if username in session['username']:
NameError: name 'username' is not defined
2021-03-30 14:46:28,306- INFO -  _internal -  113 - 127.0.0.1 - - [30/Mar/2021 14:46:28] "[31m[1mGET /cogbank/1.0/getLoan/irf HTTP/1.1[0m" 400 -
2021-03-30 14:46:56,789- INFO -  _internal -  113 -  * Running on http://127.0.0.1:5000/ (Press CTRL+C to quit)
2021-03-30 14:46:59,359- INFO -  _internal -  113 - 127.0.0.1 - - [30/Mar/2021 14:46:59] "[37mGET /cogbank/1.0/getLoan/irf HTTP/1.1[0m" 200 -
2021-03-30 14:47:13,822- INFO -  _internal -  113 - 127.0.0.1 - - [30/Mar/2021 14:47:13] "[37mGET /cogbank/1.0/logout/irf HTTP/1.1[0m" 200 -
2021-03-30 14:47:15,567- INFO -  _internal -  113 - 127.0.0.1 - - [30/Mar/2021 14:47:15] "[37mGET /cogbank/1.0/logout/irf HTTP/1.1[0m" 200 -
2021-03-30 14:47:55,399- INFO -  _internal -  113 - 127.0.0.1 - - [30/Mar/2021 14:47:55] "[37mGET /cogbank/1.0/getLoan/irf HTTP/1.1[0m" 200 -
2021-03-30 14:48:26,065- INFO -  _internal -  113 - 127.0.0.1 - - [30/Mar/2021 14:48:26] "[37mGET /cogbank/1.0/getLoan/irf HTTP/1.1[0m" 200 -
2021-03-30 14:48:31,135- INFO -  _internal -  113 - 127.0.0.1 - - [30/Mar/2021 14:48:31] "[37mGET /cogbank/1.0/logout/irf HTTP/1.1[0m" 200 -
2021-03-30 14:48:46,673- INFO -  _internal -  113 - 127.0.0.1 - - [30/Mar/2021 14:48:46] "[37mGET /cogbank/1.0/logout/dema HTTP/1.1[0m" 200 -
2021-03-30 14:48:55,346- ERROR -  app -  397 - 'username'
Traceback (most recent call last):
  File "C:\Users\javacloudmc597\Documents\PythonLearning\Day12\app.py", line 374, in getLoan
    if customer in session['username']:
  File "c:\users\javacloudmc597\.virtualenvs\day12-bmnoo7rb\lib\site-packages\werkzeug\local.py", line 377, in <lambda>
    __getitem__ = lambda x, i: x._get_current_object()[i]
  File "c:\users\javacloudmc597\.virtualenvs\day12-bmnoo7rb\lib\site-packages\flask\sessions.py", line 84, in __getitem__
    return super(SecureCookieSession, self).__getitem__(key)
KeyError: 'username'
2021-03-30 14:48:55,378- INFO -  _internal -  113 - 127.0.0.1 - - [30/Mar/2021 14:48:55] "[31m[1mGET /cogbank/1.0/getLoan/irf HTTP/1.1[0m" 400 -
2021-03-30 14:50:41,340- INFO -  _internal -  113 -  * Running on http://127.0.0.1:5000/ (Press CTRL+C to quit)
2021-03-30 14:50:44,325- ERROR -  app -  397 - 'username'
Traceback (most recent call last):
  File "C:\Users\javacloudmc597\Documents\PythonLearning\Day12\app.py", line 374, in getLoan
    if customer in session['username']:
  File "c:\users\javacloudmc597\.virtualenvs\day12-bmnoo7rb\lib\site-packages\werkzeug\local.py", line 377, in <lambda>
    __getitem__ = lambda x, i: x._get_current_object()[i]
  File "c:\users\javacloudmc597\.virtualenvs\day12-bmnoo7rb\lib\site-packages\flask\sessions.py", line 84, in __getitem__
    return super(SecureCookieSession, self).__getitem__(key)
KeyError: 'username'
2021-03-30 14:50:44,327- INFO -  _internal -  113 - 127.0.0.1 - - [30/Mar/2021 14:50:44] "[31m[1mGET /cogbank/1.0/getLoan/irf HTTP/1.1[0m" 400 -
2021-03-30 14:51:29,779- ERROR -  app -  397 - 'username'
Traceback (most recent call last):
  File "C:\Users\javacloudmc597\Documents\PythonLearning\Day12\app.py", line 374, in getLoan
    if customer in session['username']:
  File "c:\users\javacloudmc597\.virtualenvs\day12-bmnoo7rb\lib\site-packages\werkzeug\local.py", line 377, in <lambda>
    __getitem__ = lambda x, i: x._get_current_object()[i]
  File "c:\users\javacloudmc597\.virtualenvs\day12-bmnoo7rb\lib\site-packages\flask\sessions.py", line 84, in __getitem__
    return super(SecureCookieSession, self).__getitem__(key)
KeyError: 'username'
2021-03-30 14:51:29,781- INFO -  _internal -  113 - 127.0.0.1 - - [30/Mar/2021 14:51:29] "[31m[1mGET /cogbank/1.0/getLoan/dema HTTP/1.1[0m" 400 -
2021-03-30 14:53:15,296- INFO -  _internal -  113 - 127.0.0.1 - - [30/Mar/2021 14:53:15] "[37mPOST /cogbank/1.0/login/ HTTP/1.1[0m" 200 -
2021-03-30 14:53:19,881- INFO -  _internal -  113 - 127.0.0.1 - - [30/Mar/2021 14:53:19] "[37mGET /cogbank/1.0/getLoan/dema HTTP/1.1[0m" 200 -
2021-03-30 14:54:02,555- INFO -  _internal -  113 - 127.0.0.1 - - [30/Mar/2021 14:54:02] "[37mGET /cogbank/1.0/getLoan/irf HTTP/1.1[0m" 200 -
2021-03-30 14:54:11,907- INFO -  _internal -  113 - 127.0.0.1 - - [30/Mar/2021 14:54:11] "[37mGET /cogbank/1.0/logout/irf HTTP/1.1[0m" 200 -
2021-03-30 14:55:07,818- INFO -  _internal -  113 - 127.0.0.1 - - [30/Mar/2021 14:55:07] "[37mGET /cogbank/1.0/logout/irf HTTP/1.1[0m" 200 -
2021-03-30 14:55:14,814- INFO -  _internal -  113 - 127.0.0.1 - - [30/Mar/2021 14:55:14] "[37mGET /cogbank/1.0/getCustomer/irf HTTP/1.1[0m" 200 -
2021-03-30 14:55:54,619- INFO -  _internal -  113 - 127.0.0.1 - - [30/Mar/2021 14:55:54] "[37mGET /cogbank/1.0/getLoan/dema HTTP/1.1[0m" 200 -
2021-03-30 14:55:59,154- INFO -  _internal -  113 - 127.0.0.1 - - [30/Mar/2021 14:55:59] "[37mPOST /cogbank/1.0/login/ HTTP/1.1[0m" 200 -
2021-03-30 14:56:02,170- INFO -  _internal -  113 - 127.0.0.1 - - [30/Mar/2021 14:56:02] "[37mGET /cogbank/1.0/getLoan/dema HTTP/1.1[0m" 200 -
2021-03-30 14:56:17,368- INFO -  _internal -  113 -  * Running on http://127.0.0.1:5000/ (Press CTRL+C to quit)
2021-03-30 14:56:20,907- INFO -  _internal -  113 - 127.0.0.1 - - [30/Mar/2021 14:56:20] "[37mGET /cogbank/1.0/getLoan/dema HTTP/1.1[0m" 200 -
2021-03-30 14:56:30,277- INFO -  _internal -  113 - 127.0.0.1 - - [30/Mar/2021 14:56:30] "[37mGET /cogbank/1.0/logout/dema HTTP/1.1[0m" 200 -
2021-03-30 14:56:32,923- INFO -  _internal -  113 - 127.0.0.1 - - [30/Mar/2021 14:56:32] "[37mGET /cogbank/1.0/getLoan/dema HTTP/1.1[0m" 200 -
2021-03-30 14:56:39,318- ERROR -  app -  293 - {'Status': 'Please log in to get customer details'}
2021-03-30 14:56:39,319- INFO -  _internal -  113 - 127.0.0.1 - - [30/Mar/2021 14:56:39] "[33mGET /cogbank/1.0/getCustomer/dema HTTP/1.1[0m" 404 -
2021-03-30 14:56:52,372- ERROR -  app -  293 - {'Status': 'Please log in to get customer details'}
2021-03-30 14:56:52,373- INFO -  _internal -  113 - 127.0.0.1 - - [30/Mar/2021 14:56:52] "[33mGET /cogbank/1.0/getCustomer/irf HTTP/1.1[0m" 404 -
2021-03-30 14:56:59,997- INFO -  _internal -  113 - 127.0.0.1 - - [30/Mar/2021 14:56:59] "[37mGET /cogbank/1.0/getLoan/irf HTTP/1.1[0m" 200 -
2021-03-30 14:57:04,068- INFO -  _internal -  113 - 127.0.0.1 - - [30/Mar/2021 14:57:04] "[37mPOST /cogbank/1.0/login/ HTTP/1.1[0m" 200 -
2021-03-30 14:57:07,476- INFO -  _internal -  113 - 127.0.0.1 - - [30/Mar/2021 14:57:07] "[37mGET /cogbank/1.0/getLoan/irf HTTP/1.1[0m" 200 -
2021-03-30 14:57:13,613- INFO -  _internal -  113 - 127.0.0.1 - - [30/Mar/2021 14:57:13] "[37mGET /cogbank/1.0/getCustomer/dema HTTP/1.1[0m" 200 -
2021-03-30 14:57:19,706- INFO -  _internal -  113 - 127.0.0.1 - - [30/Mar/2021 14:57:19] "[37mGET /cogbank/1.0/getCustomer/irf HTTP/1.1[0m" 200 -
2021-03-30 14:57:45,188- ERROR -  app -  304 - {'Status': 'The user is not registered'}
2021-03-30 14:57:45,189- INFO -  _internal -  113 - 127.0.0.1 - - [30/Mar/2021 14:57:45] "[33mGET /cogbank/1.0/getCustomer/abcd HTTP/1.1[0m" 404 -
2021-03-30 14:58:04,937- INFO -  _internal -  113 - 127.0.0.1 - - [30/Mar/2021 14:58:04] "[37mGET /cogbank/1.0/logout/dema HTTP/1.1[0m" 200 -
2021-03-30 14:58:09,507- INFO -  _internal -  113 - 127.0.0.1 - - [30/Mar/2021 14:58:09] "[37mGET /cogbank/1.0/getLoan/irf HTTP/1.1[0m" 200 -
